Let's break it down **step by step** to understand how `requestHandler(req, res, next)` executes the original function.

---

## **Understanding Execution Flow**

### **1️⃣ What Happens When We Use `asyncHandler`?**
When you write:
```javascript
app.get("/users", asyncHandler(async (req, res, next) => {
    const users = await User.find();
    res.json(users);
}));
```
- You are passing an **async function** (your route handler) to `asyncHandler`
- `asyncHandler` **returns a new function**
- Express uses the **returned function**, not the original one yet

---

### **2️⃣ What Happens Inside `asyncHandler`?**
#### **`asyncHandler` definition:**
```javascript
const asyncHandler = (requestHandler) => {
    return (req, res, next) => {
        Promise.resolve(
            requestHandler(req, res, next)  // Calls the actual async function
        ).catch((err) => next(err));
    };
};
```
Here’s what happens when Express calls the returned function:

---

### **3️⃣ How Does `requestHandler(req, res, next)` Execute?**
- `requestHandler` is actually the original **async function** you passed:
  ```javascript
  async (req, res, next) => {
      const users = await User.find();
      res.json(users);
  }
  ```
- When Express calls the returned function `(req, res, next) => { ... }`, it **immediately calls `requestHandler(req, res, next)`** inside `Promise.resolve()`.
- This executes:
  ```javascript
  const users = await User.find();
  res.json(users);
  ```
  - `await User.find();` **fetches data**
  - `res.json(users);` **sends the response**
  - If an error occurs, `.catch((err) => next(err))` **catches it and sends it to Express**

---

## **🔹 Breaking It Down Step by Step**
1️⃣ `asyncHandler` receives the function you pass:  
   ```javascript
   async (req, res, next) => { ... }
   ```
   - This function is now stored as `requestHandler`

2️⃣ `asyncHandler` **returns** a new function:
   ```javascript
   (req, res, next) => {
       Promise.resolve(requestHandler(req, res, next)).catch((err) => next(err));
   }
   ```

3️⃣ When Express receives a request to `/users`, it **calls the returned function**:
   ```javascript
   (req, res, next) => { ... }
   ```

4️⃣ Inside this function, we **call the original function** (`requestHandler(req, res, next)`):
   ```javascript
   requestHandler(req, res, next);
   ```

5️⃣ The original function runs:
   ```javascript
   const users = await User.find();
   res.json(users);
   ```
   - **If everything works fine:** It sends the response  
   - **If an error occurs:** `.catch((err) => next(err))` **handles it**  

---

## **🎯 Simplified Example**
Imagine:
- `asyncHandler` is a **wrapper**
- The function inside is your **actual API logic**
- The returned function **executes** your original function inside `Promise.resolve()`

### **Example: Without `asyncHandler`**
```javascript
app.get("/users", async (req, res, next) => {
    try {
        const users = await User.find();
        res.json(users);
    } catch (error) {
        next(error);  // Pass error to Express error handler
    }
});
```
- We **manually** catch errors using `try-catch`.

### **Example: With `asyncHandler`**
```javascript
app.get("/users", asyncHandler(async (req, res, next) => {
    const users = await User.find();
    res.json(users);
}));
```
- `asyncHandler` **automates** error handling.
- It **calls** the original function inside `Promise.resolve()`, so we **don’t need `try-catch` manually**.

---

## **🔹 Key Takeaways**
✅ `requestHandler(req, res, next)` **executes the original function**  
✅ **It happens inside `Promise.resolve()`**, so any error is caught automatically  
✅ The returned function is **what Express actually calls**  
✅ The original function **runs as expected, but with built-in error handling**  

This **simplifies async error handling** in Express. 🚀